Workbook

Sheet 202507
A1: 报销形式 | B1: 公司 | C1: 审批编码 | D1: 姓名 | E1: 部门-详 | F1: 部门 | G1: 费用科目 | H1: 费用摘要 | I1: 日期 | J1: 差旅费交通 | K1: 住宿费 | L1: 文印快递 | M1: 招待费 | N1: 市内交通 | O1: 油费 | P1: 过路过桥停车费 | Q1: 团建费 | R1: 固定资产 | S1: IT建设 | T1: 福利费 | U1: 办公费 | V1: 维修费 | W1: 市场费 | X1: 会务费 | Y1: 通讯费 | Z1: 出差餐补 | AA1: 其他 | AB1: 小计 | AC1: 发票数量
A2: 一般报销 | B2: 无锡泊客 | C2: 202507211042000152066 | D2: 周肖琪 | E2: HR-HR01 | F2: HR | G2: =_xlfn.XLOOKUP(D2,[1]费用科目!A:A,[1]费用科目!C:C) -> 管理费用 | H2: 快递费 | I2: 2025-07-21 | N2: 34 | AB2: =SUM(J2:AA2) -> 34 | AC2: 1
A3: 一般报销 | B3: 无锡泊客 | C3: 202507192208000214911 | D3: 沈思 | E3: Revenue Recovery-Pido Team | F3: Revenue Recovery | G3: =VLOOKUP(D3,[1]费用科目!A:C,3,0) -> 管理费用 | H3: 加班打车 | I3: 2025-07-19 | N3: 85.68 | AB3: =SUM(J3:AA3) -> 85.68 | AC3: 4
A4: 一般报销 | B4: 无锡泊客 | C4: 202507191950000173809 | D4: 章琦 | E4: Yumin Team-Cocoa Team-DSP Team | F4: Yumin Team | G4: =VLOOKUP(D4,[1]费用科目!A:C,3,0) -> 管理费用 | H4: 加班打车 | I4: 2025-07-19 | N4: 15.22 | AB4: =SUM(J4:AA4) -> 15.22 | AC4: 1
A5: 一般报销 | B5: 无锡泊客 | C5: 202507211528000439864 | D5: 袁丽娟 | E5: HR-HR01 | F5: HR | G5: =VLOOKUP(D5,[1]费用科目!A:C,3,0) -> 管理费用 | H5: 快递费&市内交通&软件费 | I5: 2025-07-21 | L5: 233.9 | N5: 58.1 | S5: 3500 | AB5: =SUM(J5:AA5) -> 3792 | AC5: 4
A6: 一般报销 | B6: 无锡泊客 | C6: 202507211303000360816 | D6: 赵凤新 | E6: PM&UED-PM | F6: PM&UED | G6: =VLOOKUP(D6,[1]费用科目!A:C,3,0) -> 研发费用 | H6: 签证费 | I6: 2025-07-21 | AA6: 3500 | AB6: =SUM(J6:AA6) -> 3500 | AC6: 1
A7: 一般报销 | B7: 无锡泊客 | C7: 202507211559000024466 | D7: 马晴 | E7: Revenue Recovery | F7: Revenue Recovery | G7: =VLOOKUP(D7,[1]费用科目!A:C,3,0) -> 管理费用 | H7: 加班打车 | I7: 2025-07-21 | N7: 96 | AB7: =SUM(J7:AA7) -> 96 | AC7: 12
A8: 一般报销 | B8: 无锡泊客 | C8: 202507181812000450754 | D8: 宋薇 | E8: Yumin Team-H10_SZ | F8: Yumin Team | G8: =VLOOKUP(D8,[1]费用科目!A:C,3,0) -> 管理费用 | H8: 7月15日杭州闭门会中午购买43张30元午餐餐券，以及三箱活动用水 | I8: 2025-07-18 | W8: 1434 | AB8: =SUM(J8:AA8) -> 1434 | AC8: 1
A9: 一般报销 | B9: 无锡泊客 | C9: 202507181436000461811 | D9: 顾雯雯 | E9: HR-HR01 | F9: HR | G9: =VLOOKUP(D9,[1]费用科目!A:C,3,0) -> 管理费用 | H9: 招聘费用 | I9: 2025-07-18 | N9: 30.71 | U9: 78 | AB9: =SUM(J9:AA9) -> 108.71 | AC9: 2
A10: 一般报销 | B10: 无锡泊客 | C10: 202507181412000175704 | D10: 李胤楼 | E10: HR-HR01 | F10: HR | G10: =VLOOKUP(D10,[1]费用科目!A:C,3,0) -> 管理费用 | H10: 办公费&福利费&快递费 | I10: 2025-07-18 | L10: 12 | T10: 3031.12 | U10: 4706.39 | AB10: =SUM(J10:AA10) -> 7749.51 | AC10: 11
A11: 一般报销 | B11: 无锡泊客 | C11: 202507181032000161813 | D11: 马章瑜 | E11: R&D-SMB | F11: R&D | G11: =VLOOKUP(D11,[1]费用科目!A:C,3,0) -> 研发费用 | H11: 团建费 | I11: 2025-07-18 | Q11: 6378.95 | AB11: =SUM(J11:AA11) -> 6378.95 | AC11: 11
A12: 一般报销 | B12: 无锡泊客 | C12: 202507180931000237464 | D12: 皇甫苗苗 | E12: R&D-QA&PMO-QA-Test-Commerce Test Team | F12: R&D | G12: =VLOOKUP(D12,[1]费用科目!A:C,3,0) -> 研发费用 | H12: 加班打车 | I12: 2025-07-18 | N12: 111.72 | AB12: =SUM(J12:AA12) -> 111.72 | AC12: 8
A13: 一般报销 | B13: 无锡泊客 | C13: 202507172207000168100 | D13: 李璐 | E13: R&D-QA&PMO-QA-Test-Helium 10 Test Team | F13: R&D | G13: =VLOOKUP(D13,[1]费用科目!A:C,3,0) -> 研发费用 | H13: 加班打车 | I13: 2025-07-17 | N13: 45.4 | AB13: =SUM(J13:AA13) -> 45.4 | AC13: 1
A14: 一般报销 | B14: 无锡泊客 | C14: 202507171810000106051 | D14: 吉羽 | E14: R&D-Enterprise-Corporate IT | F14: R&D | G14: =VLOOKUP(D14,[1]费用科目!A:C,3,0) -> 研发费用 | H14: 快递费 | I14: 2025-07-17 | L14: 127 | AB14: =SUM(J14:AA14) -> 127 | AC14: 1
A15: 一般报销 | B15: 无锡泊客 | C15: 202507171350000515422 | D15: 殷子心 | E15: R&D-Enterprise | F15: R&D | G15: =VLOOKUP(D15,[1]费用科目!A:C,3,0) -> 研发费用 | H15: 团建费 | I15: 2025-07-17 | Q15: 7101.35 | S15: 2982.03 | AB15: =SUM(J15:AA15) -> 10083.38 | AC15: 9
A16: 一般报销 | B16: 无锡泊客 | C16: 202507170851000339693 | D16: 管燕山 | E16: R&D-Enterprise-Commerce-Front End | F16: R&D | G16: =VLOOKUP(D16,[1]费用科目!A:C,3,0) -> 研发费用 | H16: 加班打车 | I16: 2025-07-17 | N16: 75.8 | AB16: =SUM(J16:AA16) -> 75.8 | AC16: 2
A17: 一般报销 | B17: 无锡泊客 | C17: 202507161335000493772 | D17: 蔡佳菡 | E17: HR-HR01 | F17: HR | G17: =VLOOKUP(D17,[1]费用科目!A:C,3,0) -> 管理费用 | H17: 办公费&福利费 | I17: 2025-07-16 | T17: 3179.37 | U17: 296.21 | AB17: =SUM(J17:AA17) -> 3475.58 | AC17: 15
A18: 一般报销 | B18: 无锡泊客 | C18: 202507161108000216812 | D18: 李凯 | E18: PM&UED-UED Enterprise | F18: PM&UED | G18: =VLOOKUP(D18,[1]费用科目!A:C,3,0) -> 研发费用 | H18: 差旅费 | I18: 2025-07-16 | J18: 106 | AB18: =SUM(J18:AA18) -> 106 | AC18: 2
A19: 一般报销 | B19: 无锡泊客 | C19: 202507161010000118303 | D19: 方玲 | E19: R&D-QA&PMO-QA-Test-Middle Platform Test Team | F19: R&D | G19: =VLOOKUP(D19,[1]费用科目!A:C,3,0) -> 研发费用 | H19: 加班打车 | I19: 2025-07-16 | N19: 145 | AB19: =SUM(J19:AA19) -> 145 | AC19: 2
A20: 一般报销 | B20: 无锡泊客 | C20: 202507160954000380059 | D20: 葛成杰 | E20: R&D-Enterprise-Commerce-Front End | F20: R&D | G20: =VLOOKUP(D20,[1]费用科目!A:C,3,0) -> 研发费用 | H20: 加班打车 | I20: 2025-07-16 | N20: 43.46 | AB20: =SUM(J20:AA20) -> 43.46 | AC20: 1
A21: 一般报销 | B21: 无锡泊客 | C21: 202507160950000185179 | D21: 李振强 | E21: R&D-Enterprise-Commerce-Front End | F21: R&D | G21: =VLOOKUP(D21,[1]费用科目!A:C,3,0) -> 研发费用 | H21: 加班打车 | I21: 2025-07-16 | N21: 346.6 | AB21: =SUM(J21:AA21) -> 346.6 | AC21: 1
A22: 一般报销 | B22: 无锡泊客 | C22: 202507160940000564273 | D22: 梅宝文 | E22: R&D-QA&PMO-QA-Test-Commerce Test Team | F22: R&D | G22: =VLOOKUP(D22,[1]费用科目!A:C,3,0) -> 研发费用 | H22: 加班打车 | I22: 2025-07-16 | N22: 35.05 | AB22: =SUM(J22:AA22) -> 35.05 | AC22: 3
A23: 一般报销 | B23: 无锡泊客 | C23: 202507160935000249026 | D23: 陈雨 | E23: R&D-Enterprise-Commerce-Content Management | F23: R&D | G23: =VLOOKUP(D23,[1]费用科目!A:C,3,0) -> 研发费用 | H23: 加班打车 | I23: 2025-07-16 | N23: 56.08 | AB23: =SUM(J23:AA23) -> 56.08 | AC23: 1
A24: 一般报销 | B24: 无锡泊客 | C24: 202507101013000457377 | D24: 刘瑞敏 | E24: R&D-QA&PMO-QA-Test-Helium 10 Test Team | F24: R&D | G24: =VLOOKUP(D24,[1]费用科目!A:C,3,0) -> 研发费用 | H24: 加班打车 | I24: 2025-07-10 | N24: 50.83 | AB24: =SUM(J24:AA24) -> 50.83 | AC24: 1
A25: 一般报销 | B25: 无锡泊客 | C25: 202507091435000573640 | D25: 高晓晨 | E25: Yumin Team-Cocoa Team-CS Team | F25: Yumin Team | G25: =VLOOKUP(D25,[1]费用科目!A:C,3,0) -> 管理费用 | H25: 差旅费 | I25: 2025-07-09 | J25: 424 | N25: 73.76 | AB25: =SUM(J25:AA25) -> 497.76 | AC25: 5
A26: 一般报销 | B26: 无锡泊客 | C26: 202507091037000361675 | D26: 魏宁玲 | E26: Yumin Team-Cocoa Team-CS Team | F26: Yumin Team | G26: =VLOOKUP(D26,[1]费用科目!A:C,3,0) -> 管理费用 | H26: 差旅费 | I26: 2025-07-09 | J26: 424 | N26: 27.71 | AB26: =SUM(J26:AA26) -> 451.71 | AC26: 3
A27: 一般报销 | B27: 无锡泊客 | C27: 202507081213000517920 | D27: 丁力 | E27: R&D-Enterprise-Commerce | F27: R&D | G27: =VLOOKUP(D27,[1]费用科目!A:C,3,0) -> 研发费用 | H27: 面签&快递费&签证费 | I27: 2025-07-08 | J27: 538 | K27: 119.75 | L27: 110 | AA27: 1368 | AB27: =SUM(J27:AA27) -> 2135.75 | AC27: 5
A28: 一般报销 | B28: 无锡泊客 | C28: 202507071439000161192 | D28: 姬礼 | E28: R&D-QA&PMO-QA-Test-Middle Platform Test Team | F28: R&D | G28: =VLOOKUP(D28,[1]费用科目!A:C,3,0) -> 研发费用 | H28: 加班打车 | I28: 2025-07-07 | N28: 30 | AB28: =SUM(J28:AA28) -> 30 | AC28: 1
A29: 一般报销 | B29: 无锡泊客 | C29: 202507071203000291523 | D29: 张安谊 | E29: R&D-Enterprise-Corporate IT | F29: R&D | G29: =VLOOKUP(D29,[1]费用科目!A:C,3,0) -> 研发费用 | H29: 团建费 | I29: 2025-07-07 | Q29: 1102 | AB29: =SUM(J29:AA29) -> 1102 | AC29: 1
A30: 一般报销 | B30: 无锡泊客 | C30: 202507040959000114870 | D30: 李璐 | E30: R&D-QA&PMO-QA-Test-Helium 10 Test Team | F30: R&D | G30: =VLOOKUP(D30,[1]费用科目!A:C,3,0) -> 研发费用 | H30: 加班打车 | I30: 2025-07-04 | Q30: 212.7 | AB30: =SUM(J30:AA30) -> 212.7 | AC30: 1
A31: 一般报销 | B31: 无锡泊客 | C31: 202507011047000578303 | D31: 马章瑜 | E31: R&D-SMB | F31: R&D | G31: =VLOOKUP(D31,[1]费用科目!A:C,3,0) -> 研发费用 | H31: 团建费 | I31: 2025-07-01 | Q31: 845.97 | AB31: =SUM(J31:AA31) -> 845.97 | AC31: 2
A32: 一般报销 | B32: 无锡泊客 | C32: 202506302054000237319 | D32: 费冬梅 | E32: Yumin Team-Cocoa Team-DSP Team | F32: Yumin Team | G32: =VLOOKUP(D32,[1]费用科目!A:C,3,0) -> 管理费用 | H32: 加班打车 | I32: 2025-06-30 | N32: 130.3 | AB32: =SUM(J32:AA32) -> 130.3 | AC32: 1
A33: 一般报销 | B33: 无锡泊客 | C33: 202506271213000003160 | D33: 周盼盼 | E33: R&D-QA&PMO-QA-Test-Commerce Test Team | F33: R&D | G33: =VLOOKUP(D33,[1]费用科目!A:C,3,0) -> 研发费用 | H33: 加班打车 | I33: 2025-06-27 | N33: 33.13 | AB33: =SUM(J33:AA33) -> 33.13 | AC33: 1
A34: 一般报销 | B34: 无锡泊客 | C34: 202506271208000562306 | D34: 周盼盼 | E34: R&D-QA&PMO-QA-Test-Commerce Test Team | F34: R&D | G34: =VLOOKUP(D34,[1]费用科目!A:C,3,0) -> 研发费用 | H34: 加班打车 | I34: 2025-06-27 | N34: 178.3 | AB34: =SUM(J34:AA34) -> 178.3 | AC34: 1
A35: 一般报销 | B35: 无锡泊客 | C35: 202506241615000421229 | D35: 江正贯 | E35: R&D-Enterprise-Data ETL | F35: R&D | G35: =VLOOKUP(D35,[1]费用科目!A:C,3,0) -> 研发费用 | H35: 软件服务费 | I35: 2025-06-24 | S35: 2028 | AB35: =SUM(J35:AA35) -> 2028 | AC35: 1
A36: 一般报销 | B36: 无锡泊客 | C36: 202507171708000235667 | D36: 王宇锋 | E36: R&D-SMB-Offline Data Processing-Data Acquisition | F36: R&D | G36: =VLOOKUP(D36,[1]费用科目!A:C,3,0) -> 研发费用 | H36: CN IP 代理 | I36: 2025-07-17 | S36: 7160 | AB36: =SUM(J36:AA36) -> 7160 | AC36: 1
A37: 一般报销 | B37: 无锡泊客 | C37: 202507181425000591672 | D37: 张云云 | E37: HR-HR01 | F37: HR | G37: =VLOOKUP(D37,[1]费用科目!A:C,3,0) -> 管理费用 | H37: 快递费 | I37: 2025-07-18 | N37: 126.24 | AB37: =SUM(J37:AA37) -> 126.24 | AC37: 2
A38: 差旅费报销 | B38: 无锡泊客 | C38: 202507211633000265858 | D38: 殷子心 | E38: R&D | F38: R&D | G38: =VLOOKUP(D38,[1]费用科目!A:C,3,0) -> 研发费用 | H38: 出差1天 | I38: 2025-07-21 | J38: 126 | N38: 84.2 | AB38: =SUM(J38:AA38) -> 210.2 | AC38: 4
A39: 差旅费报销 | B39: 无锡泊客 | C39: 202507181921000193069 | D39: 马晴 | E39: Revenue Recovery | F39: Revenue Recovery | G39: =VLOOKUP(D39,[1]费用科目!A:C,3,0) -> 管理费用 | H39: 出差1天 | I39: 2025-07-18 | N39: 90.09 | AB39: =SUM(J39:AA39) -> 90.09 | AC39: 2
A40: 差旅费报销 | B40: 无锡泊客 | C40: 202507192219000356946 | D40: 沈思 | E40: Revenue Recovery-Pido Team | F40: Revenue Recovery | G40: =VLOOKUP(D40,[1]费用科目!A:C,3,0) -> 管理费用 | H40: 出差3天 | I40: 2025-07-19 | N40: 403.05 | AB40: =SUM(J40:AA40) -> 403.05 | AC40: 5
...
